Workbook

Sheet 표지
D2: SKN-29_1st_prj_2team
A5: DB 테이블 명세서
S9: SKN-29_1st_prj_2team
S10: Ver. 1.0
P15: Road To Commit
A25: Copyright ⓒ Road To Commit

Sheet 개정이력
C5: 개정이력
C8: 버전 | D8: 변경일 | E8: 변경내용1) | F8: 작성자 | G8: 검토자 | H8: 승인자
C9: 0.1 | D9: 45744 | E9: 최초작성 | F9: 김재홍 | G9: 우리조 | H9: 우리조
C10: 0.2 | D10: 45745 | E10: 테이블명세 추가 | F10: 김재홍 | G10: 우리조 | H10: 우리조
C11: 1.0 | D11: 45747 | E11: 테이블명세서 v1.0 | F11: 김재홍 | G11: 우리조 | H11: 우리조
C23: 주1) 변경내용 : 변경이 발생되는 위치와 변경 내용을 자세히 기록(장/절)과 변경 내용을 기술

Sheet 테이블명세서
A1: Table Specification
A2: 시스템/서비스 | G2: 자동차 시장 분석 및 의사결정 지원 플랫폼
A3: 작성자 | G3: 김재홍, 김정민, 김지훈, 정영석
A4: 작성일 | G4: 45747
A5: 프로젝트명 | G5: SKN-29_PRJ1__2team_자동차 시장 분석 및 의사결정 지원 플랫폼
A6: dbms | G6: MySQL
A7: db_name | G7: car_db
A8: schema_name | G8: car_db
A10: 테이블명 | C10: 연령-성별-시도 차량등록 현황 테이블 | E10: table_number | G10: 1 | I10: table_name | L10: age_gender_sido
A11: no | B11: db_name | C11: schema_name | D11: table_name | E11: table_number | F11: column_name | G11: 컬럼명 | H11: type | I11: length | J11: Key | K11: Unique | L11: NN | M11: Default | N11: 정의/설명 | O11: 참조테이블 | P11: 비고
A12: 1 | B12: =$G$7 -> car_db | C12: =$G$8 -> car_db | D12: =$L$10 -> age_gender_sido | E12: 1 | F12: time_id | G12: 행번호 | H12: int | J12: PRI | L12: NOT NULL | M12: AUTO_INCREMENT | N12: 각 테이블의 고유 행 식별
A13: 2 | B13: =$G$7 -> car_db | C13: =$G$8 -> car_db | D13: =$L$10 -> age_gender_sido | E13: 1 | F13: sido_id | G13: 시도id명 | H13: int | J13: PRI | L13: NOT NULL
A14: 3 | B14: =$G$7 -> car_db | C14: =$G$8 -> car_db | D14: =$L$10 -> age_gender_sido | E14: 1 | F14: gender | G14: 성별구분 | H14: varchar(10) | J14: PRI | L14: NOT NULL
A15: 4 | B15: =$G$7 -> car_db | C15: =$G$8 -> car_db | D15: =$L$10 -> age_gender_sido | E15: 1 | F15: age | G15: 나이구분 | H15: int | J15: PRI | L15: NOT NULL
A16: 5 | B16: =$G$7 -> car_db | C16: =$G$8 -> car_db | D16: =$L$10 -> age_gender_sido | E16: 1 | F16: count | G16: 차량등록수 | H16: int
A18: 테이블명 | C18: 지역별 차량등록 현황 테이블 | E18: table_number | G18: 2 | I18: table_name | L18: car_sigungu
A19: no | B19: db_name | C19: schema_name | D19: table_name | E19: table_number | F19: column_name | G19: 컬럼명 | H19: type | I19: length | J19: Key | K19: Unique | L19: NOT NULL | M19: Default | N19: 정의/설명 | O19: 참조테이블 | P19: 비고
A20: 1 | B20: =$G$7 -> car_db | C20: =$G$8 -> car_db | D20: =$L$18 -> car_sigungu | E20: 2 | F20: time_id | G20: 행번호 | H20: int | J20: PRI | L20: NOT NULL | M20: AUTO_INCREMENT | N20: 각 테이블의 고유 행 식별
A21: 2 | B21: =$G$7 -> car_db | C21: =$G$8 -> car_db | D21: =$L$18 -> car_sigungu | E21: 2 | F21: region_id | G21: 지역id명 | H21: int | J21: PRI | L21: NOT NULL
A22: 3 | B22: =$G$7 -> car_db | C22: =$G$8 -> car_db | D22: =$L$18 -> car_sigungu | E22: 2 | F22: passenger_private | G22: 승용차량 등록수(자가) | H22: int
A23: 4 | B23: =$G$7 -> car_db | C23: =$G$8 -> car_db | D23: =$L$18 -> car_sigungu | E23: 2 | F23: passenger_total | G23: 승용차량 등록수(자가+기타) | H23: int
A25: 테이블명 | C25: 시도 누적 차량등록 현황 테이블 | E25: table_number | G25: 3 | I25: table_name | L25: cumul_sido
A26: no | B26: db_name | C26: schema_name | D26: table_name | E26: table_number | F26: column_name | G26: 컬럼명 | H26: type | I26: length | J26: Key | K26: Unique | L26: NN | M26: Default | N26: 정의/설명 | O26: 참조테이블 | P26: 비고
A27: 1 | B27: =$G$7 -> car_db | C27: =$G$8 -> car_db | D27: =$L$25 -> cumul_sido | E27: 3 | F27: time_id | G27: 행번호 | H27: int | J27: PRI | L27: NOT NULL | M27: AUTO_INCREMENT | N27: 각 테이블의 고유 행 식별
A28: 2 | B28: =$G$7 -> car_db | C28: =$G$8 -> car_db | D28: =$L$25 -> cumul_sido | E28: 3 | F28: sido_id | G28: 시도id | H28: int | J28: PRI | L28: NOT NULL
A29: 3 | B29: =$G$7 -> car_db | C29: =$G$8 -> car_db | D29: =$L$25 -> cumul_sido | E29: 3 | F29: passenger_cumulcar | G29: 누적 차량등록수(국산) | H29: int
A30: 4 | B30: =$G$7 -> car_db | C30: =$G$8 -> car_db | D30: =$L$25 -> cumul_sido | E30: 3 | F30: passenger_cumulimportedcar | G30: 누적 차량등록수(외산) | H30: int
A32: 테이블명 | C32: 지역 테이블 | E32: table_number | G32: 4 | I32: table_name | L32: dim_region
A33: no | B33: db_name | C33: schema_name | D33: table_name | E33: table_number | F33: column_name | G33: 컬럼명 | H33: type | I33: length | J33: Key | K33: Unique | L33: NN | M33: Default | N33: 정의/설명 | O33: 참조테이블 | P33: 비고
A34: 1 | B34: =$G$7 -> car_db | C34: =$G$8 -> car_db | D34: =$L$32 -> dim_region | E34: 3 | F34: region_id | G34: 지역id | H34: int | J34: PRI | L34: NOT NULL | M34: AUTO_INCREMENT | N34: 각 테이블의 고유 행 식별
A35: 2 | B35: =$G$7 -> car_db | C35: =$G$8 -> car_db | D35: =$L$32 -> dim_region | E35: 3 | F35: sido_id | G35: 시도id | H35: int | J35: MUL | L35: NOT NULL
A36: 3 | B36: =$G$7 -> car_db | C36: =$G$8 -> car_db | D36: =$L$32 -> dim_region | E36: 3 | F36: sigungu | G36: 시군구명 | H36: varchar(20) | L36: NOT NULL
A38: 테이블명 | C38: 시도 테이블 | E38: table_number | G38: 5 | I38: table_name | L38: dim_sido
A39: no | B39: db_name | C39: schema_name | D39: table_name | E39: table_number | F39: column_name | G39: 컬럼명 | H39: type | I39: length | J39: Key | K39: Unique | L39: NN | M39: Default | N39: 정의/설명 | O39: 참조테이블 | P39: 비고
A40: 1 | B40: =$G$7 -> car_db | C40: =$G$8 -> car_db | D40: =$L$38 -> dim_sido | E40: 4 | F40: sido_id | G40: 시도id | H40: int | J40: PRI | L40: NOT NULL | M40: AUTO_INCREMENT | N40: 각 테이블의 고유 행 식별
A41: 2 | B41: =$G$7 -> car_db | C41: =$G$8 -> car_db | D41: =$L$38 -> dim_sido | E41: 4 | F41: sido | G41: 시도구분 | H41: varchar(20) | J41: UNI | L41: NOT NULL
A43: 테이블명 | C43: 연월 테이블 | E43: table_number | G43: 6 | I43: table_name | L43: dim_time
A44: no | B44: db_name | C44: schema_name | D44: table_name | E44: table_number | F44: column_name | G44: 컬럼명 | H44: type | I44: length | J44: Key | K44: Unique | L44: NN | M44: Default | N44: 정의/설명 | O44: 참조테이블 | P44: 비고
A45: 1 | B45: =$G$7 -> car_db | C45: =$G$8 -> car_db | D45: =$L$43 -> dim_time | E45: 7 | F45: time_id | G45: 연월id | H45: int | J45: PRI | L45: NOT NULL | M45: AUTO_INCREMENT | N45: 각 테이블의 고유 행 식별
A46: 2 | B46: =$G$7 -> car_db | C46: =$G$8 -> car_db | D46: =$L$43 -> dim_time | E46: 7 | F46: year | G46: 연도구분 | H46: int | J46: MUL | L46: NOT NULL
...

Sheet 컬럼목록
A2: Columns List
A4: no | B4: db_name | C4: schema_name | D4: table_name | E4: table_number | F4: column_name | G4: 컬럼명 | H4: type | I4: length | J4: Key | K4: NOT NULL | L4: Default | M4: 정의/설명 | N4: 참조테이블 | O4: 비고
A5: =ROW()-4 -> 1 | B5: =테이블명세서!$G$7 -> car_db | C5: =테이블명세서!$G$8 -> car_db | D5: age_gender_sido | E5: 1 | F5: time_id | G5: 행번호 | H5: int | J5: PRI | K5: NOT NULL
A6: =ROW()-4 -> 2 | B6: =테이블명세서!$G$7 -> car_db | C6: =테이블명세서!$G$8 -> car_db | D6: age_gender_sido | E6: 1 | F6: sido_id | G6: 시도id명 | H6: int | J6: PRI | K6: NOT NULL
A7: =ROW()-4 -> 3 | B7: =테이블명세서!$G$7 -> car_db | C7: =테이블명세서!$G$8 -> car_db | D7: age_gender_sido | E7: 1 | F7: gender | G7: 성별구분 | H7: varchar(10) | J7: PRI | K7: NOT NULL
A8: =ROW()-4 -> 4 | B8: =테이블명세서!$G$7 -> car_db | C8: =테이블명세서!$G$8 -> car_db | D8: age_gender_sido | E8: 1 | F8: age | G8: 나이구분 | H8: int | J8: PRI | K8: NOT NULL
A9: =ROW()-4 -> 5 | B9: =테이블명세서!$G$7 -> car_db | C9: =테이블명세서!$G$8 -> car_db | D9: age_gender_sido | E9: 1 | F9: count | G9: 차량등록수 | H9: int
A10: =ROW()-4 -> 6 | B10: =테이블명세서!$G$7 -> car_db | C10: =테이블명세서!$G$8 -> car_db | D10: car_sigungu | E10: 2 | F10: time_id | G10: 행번호 | H10: int | J10: PRI | K10: NOT NULL
A11: =ROW()-4 -> 7 | B11: =테이블명세서!$G$7 -> car_db | C11: =테이블명세서!$G$8 -> car_db | D11: car_sigungu | E11: 2 | F11: region_id | G11: 지역id명 | H11: int | J11: PRI | K11: NOT NULL
A12: =ROW()-4 -> 8 | B12: =테이블명세서!$G$7 -> car_db | C12: =테이블명세서!$G$8 -> car_db | D12: car_sigungu | E12: 2 | F12: passenger_private | G12: 승용차량 등록수(자가) | H12: int
A13: =ROW()-4 -> 9 | B13: =테이블명세서!$G$7 -> car_db | C13: =테이블명세서!$G$8 -> car_db | D13: car_sigungu | E13: 2 | F13: passenger_total | G13: 승용차량 등록수(자가+기타) | H13: int
A14: =ROW()-4 -> 10 | B14: =테이블명세서!$G$7 -> car_db | C14: =테이블명세서!$G$8 -> car_db | D14: cumul_sido | E14: 3 | F14: time_id | G14: 행번호 | H14: int | J14: PRI | K14: NOT NULL
A15: =ROW()-4 -> 11 | B15: =테이블명세서!$G$7 -> car_db | C15: =테이블명세서!$G$8 -> car_db | D15: cumul_sido | E15: 3 | F15: sido_id | G15: 시도id | H15: int | J15: PRI | K15: NOT NULL
A16: =ROW()-4 -> 12 | B16: =테이블명세서!$G$7 -> car_db | C16: =테이블명세서!$G$8 -> car_db | D16: cumul_sido | E16: 3 | F16: passenger_cumulcar | G16: 누적 차량등록수(국산) | H16: int
A17: =ROW()-4 -> 13 | B17: =테이블명세서!$G$7 -> car_db | C17: =테이블명세서!$G$8 -> car_db | D17: cumul_sido | E17: 3 | F17: passenger_cumulimportedcar | G17: 누적 차량등록수(외산) | H17: int
A18: =ROW()-4 -> 14 | B18: =테이블명세서!$G$7 -> car_db | C18: =테이블명세서!$G$8 -> car_db | D18: dim_region | E18: 4 | F18: region_id | G18: 지역id | H18: int | J18: PRI | K18: NOT NULL
A19: =ROW()-4 -> 15 | B19: =테이블명세서!$G$7 -> car_db | C19: =테이블명세서!$G$8 -> car_db | D19: dim_region | E19: 4 | F19: sido_id | G19: 시도id | H19: int | J19: MUL | K19: NOT NULL
A20: =ROW()-4 -> 16 | B20: =테이블명세서!$G$7 -> car_db | C20: =테이블명세서!$G$8 -> car_db | D20: dim_region | E20: 4 | F20: sigungu | G20: 시군구명 | H20: varchar(20) | K20: NOT NULL
A21: =ROW()-4 -> 17 | B21: =테이블명세서!$G$7 -> car_db | C21: =테이블명세서!$G$8 -> car_db | D21: dim_sido | E21: 5 | F21: sido_id | G21: 시도id | H21: int | J21: PRI | K21: NOT NULL
A22: =ROW()-4 -> 18 | B22: =테이블명세서!$G$7 -> car_db | C22: =테이블명세서!$G$8 -> car_db | D22: dim_sido | E22: 5 | F22: sido | G22: 시도구분 | H22: varchar(20) | J22: UNI | K22: NOT NULL
A23: =ROW()-4 -> 19 | B23: =테이블명세서!$G$7 -> car_db | C23: =테이블명세서!$G$8 -> car_db | D23: dim_time | E23: 6 | F23: time_id | G23: 연월id | H23: int | J23: PRI | K23: NOT NULL
A24: =ROW()-4 -> 20 | B24: =테이블명세서!$G$7 -> car_db | C24: =테이블명세서!$G$8 -> car_db | D24: dim_time | E24: 6 | F24: year | G24: 연도구분 | H24: int | J24: MUL | K24: NOT NULL
A25: =ROW()-4 -> 21 | B25: =테이블명세서!$G$7 -> car_db | C25: =테이블명세서!$G$8 -> car_db | D25: dim_time | E25: 6 | F25: month | G25: 월구분 | H25: int | K25: NOT NULL
A26: =ROW()-4 -> 22 | B26: =테이블명세서!$G$7 -> car_db | C26: =테이블명세서!$G$8 -> car_db | D26: fuel_sido | E26: 7 | F26: time_id | G26: 연월id | H26: int | J26: PRI | K26: NOT NULL
A27: =ROW()-4 -> 23 | B27: =테이블명세서!$G$7 -> car_db | C27: =테이블명세서!$G$8 -> car_db | D27: fuel_sido | E27: 7 | F27: sido_id | G27: 시도id | H27: int | J27: PRI | K27: NOT NULL
A28: =ROW()-4 -> 24 | B28: =테이블명세서!$G$7 -> car_db | C28: =테이블명세서!$G$8 -> car_db | D28: fuel_sido | E28: 7 | F28: fuel | G28: 연료정보 | H28: varchar(50) | J28: PRI | K28: NOT NULL
A29: =ROW()-4 -> 25 | B29: =테이블명세서!$G$7 -> car_db | C29: =테이블명세서!$G$8 -> car_db | D29: fuel_sido | E29: 7 | F29: count | G29: 누적 차량등록수 | H29: int
A30: =ROW()-4 -> 26 | B30: =테이블명세서!$G$7 -> car_db | C30: =테이블명세서!$G$8 -> car_db | D30: imported_sigungu | E30: 8 | F30: time_id | G30: 연월id | H30: int | J30: PRI | K30: NOT NULL
A31: =ROW()-4 -> 27 | B31: =테이블명세서!$G$7 -> car_db | C31: =테이블명세서!$G$8 -> car_db | D31: imported_sigungu | E31: 8 | F31: region_id | G31: 지역id | H31: int | J31: PRI | K31: NOT NULL
A32: =ROW()-4 -> 28 | B32: =테이블명세서!$G$7 -> car_db | C32: =테이블명세서!$G$8 -> car_db | D32: imported_sigungu | E32: 8 | F32: passenger_imported | G32: 외산차량 등록수 | H32: int
A33: =ROW()-4 -> 29 | B33: =테이블명세서!$G$7 -> car_db | C33: =테이블명세서!$G$8 -> car_db | D33: income | E33: 9 | F33: year | G33: 연도구분 | H33: int | J33: PRI | K33: NOT NULL
A34: =ROW()-4 -> 30 | B34: =테이블명세서!$G$7 -> car_db | C34: =테이블명세서!$G$8 -> car_db | D34: income | E34: 9 | F34: region_id | G34: 지역id | H34: int | J34: PRI | K34: NOT NULL
A35: =ROW()-4 -> 31 | B35: =테이블명세서!$G$7 -> car_db | C35: =테이블명세서!$G$8 -> car_db | D35: income | E35: 9 | F35: count | G35: 지역 신고 인원수 | H35: int
A36: =ROW()-4 -> 32 | B36: =테이블명세서!$G$7 -> car_db | C36: =테이블명세서!$G$8 -> car_db | D36: income | E36: 9 | F36: income | G36: 지역 총 종합소득금액 | H36: bigint
A37: =ROW()-4 -> 33 | B37: =테이블명세서!$G$7 -> car_db | C37: =테이블명세서!$G$8 -> car_db | D37: income | E37: 9 | F37: income_per_person | G37: 1인당종합소득금액(백만원) | H37: double
A38: =ROW()-4 -> 34 | B38: =테이블명세서!$G$7 -> car_db | C38: =테이블명세서!$G$8 -> car_db | D38: model_year | E38: 10 | F38: time_id | G38: 연월id | H38: int | J38: PRI | K38: NOT NULL
A39: =ROW()-4 -> 35 | B39: =테이블명세서!$G$7 -> car_db | C39: =테이블명세서!$G$8 -> car_db | D39: model_year | E39: 10 | F39: model_year | G39: 차량연식 | H39: int | J39: PRI | K39: NOT NULL
A40: =ROW()-4 -> 36 | B40: =테이블명세서!$G$7 -> car_db | C40: =테이블명세서!$G$8 -> car_db | D40: model_year | E40: 10 | F40: passenger | G40: 승용차량 등록수(자가) | H40: int
A41: =ROW()-4 -> 37 | B41: =테이블명세서!$G$7 -> car_db | C41: =테이블명세서!$G$8 -> car_db | D41: new_foreign_domestic_sido | E41: 11 | F41: time_id | G41: 연월id | H41: int | J41: PRI | K41: NOT NULL
A42: =ROW()-4 -> 38 | B42: =테이블명세서!$G$7 -> car_db | C42: =테이블명세서!$G$8 -> car_db | D42: new_foreign_domestic_sido | E42: 11 | F42: sido_id | G42: 시도id | H42: int | J42: PRI | K42: NOT NULL
...
